Workbook

Sheet Synthèse
B1: TikTok : ce qui fait vraiment performer un contenu
B2: Synthèse pour la campagne · 300 vidéos populaires collectées en août 2021 (tendances, top #funny, vidéos likées par @tiktok). Succès = taux d'engagement = (likes + commentaires + partages) ÷ vues ; top performers = le quart supérieur de chaque échantillon. Chaque conclusion renvoie à l'onglet qui la prouve.
B4: LES CONCLUSIONS | H4: QUI SE DISTINGUE : LEADERS PAR SUJET
C5: Conclusion | D5: Chiffre clé | E5: Ce que dit le chiffre | F5: Preuve | H5: Sujet | I5: Leader d'engagement | J5: Leader de portée
B6: 1 | C6: La taille du compte ne fait pas la portée. | D6: ='Gros comptes'!C19 -> 0.28067579 | E6: Corrélation abonnés ↔ vues, faible. Dans le top 100 #funny, 36 fois plus d'abonnés (plus de 8 M contre moins de 1 M) ne donnent que 1,3 fois plus de vues médianes. | F6: → Gros comptes | H6: Animaux | I6: @www9781 | J6: @funnyvids2k21
B7: 2 | C7: Les petits comptes font davantage réagir leur audience. | D7: ='Gros comptes'!H11 -> 0.19109258 | E7: Engagement médian sous 1 M d'abonnés, contre 13,2 % au-delà de 8 M (43 % de top performers contre 10 %). Tendance à confirmer : l'écart se réduit à vues égales. | F7: → Gros comptes | H7: Famille & enfants | I7: @hayndkay_mom | J7: @mercuri_88
B8: 3 | C8: Les « recettes » de publication n'y changent rien. | D8: =Facteurs!D8 -> -0.7020077 | E8: Écart d'engagement avec ou sans #fyp/#foryou dans les tendances (p = 0,32). Jour, heure, appel à l'action, mentions, son original : aucun effet significatif dans les 3 échantillons. | F8: → Facteurs | H8: Humour & sketchs | I8: @hassankhadair | J8: @samuelgrubbs
B9: 4 | C9: Seul levier qui ressort : des vidéos un peu plus longues. | D9: =Facteurs!D6 -> 5.5086302 | E9: Vidéos de plus de 15 s : 15,6 % d'engagement contre 10,1 % dans les tendances (47 % de top performers contre 20 %, p = 0,02). Non confirmé ailleurs : à tester, pas à imposer. | F9: → Facteurs | H9: Lifestyle, musique & sport | I9: @bts_official_bighit | J9: @pimplepom
B10: 5 | C10: Aucun sujet ne gagne à coup sûr : choisir le sujet pour la marque, puis le créateur pour son engagement. | D10: =Facteurs!D17 -> 4.2214309 | E10: Écart maximal d'engagement médian entre sujets dans les tendances, non significatif (p = 0,33). Des leaders existent dans chaque sujet (ci-contre). | F10: → Catégories | H10: Sujet non déclaré | I10: @roses_are_rosie | J10: @cacha.7.griselda
H11: → 3 leaders par sujet, leurs chiffres et le TreeMap
B13: À RETENIR POUR LA CAMPAGNE (leviers que la marque et le créateur contrôlent) | H13: CE QUE CES DONNÉES NE DISENT PAS
B14: ✓ | C14: Sélectionner les créateurs sur leur taux d'engagement mesuré sur plusieurs vidéos, pas sur leur nombre d'abonnés. | H14: Ce qui fait entrer une vidéo dans les tendances : on ne voit que des succès, aucun échec à comparer.
B15: ✓ | C15: Inclure des comptes de moins de 3 M d'abonnés : sous 1 M, 25 fois plus de vues par abonné qu'au-delà de 8 M. Négocier les tarifs en conséquence. | H15: Ce qui marche aujourd'hui : données d'août 2021 ; algorithme, formats et audiences ont changé depuis.
B16: ✓ | C16: Laisser la main au créateur sur le format : ne pas imposer de hashtags « algorithme », d'horaire ni de jour de publication dans le brief. | H16: Les causes : ce sont des corrélations ; les abonnés, mesurés après coup, peuvent être une conséquence du succès.
B17: ✓ | C17: Tester en A/B des formats de 15 à 60 s contre des formats très courts, en suivant le taux d'engagement. | H17: Le retour sur investissement : ni audience (âge, pays), ni ventes, ni coût des créateurs dans les données.
B19: → | C19: Facteurs | D19: Gros comptes | E19: Catégories & TreeMap | F19: Méthode & limites | I19: Données

Sheet Facteurs
B1: Facteurs de succès : ce que le créateur contrôle… et ce qui n'y change rien
B2: Lecture : pour chaque levier, écart de taux d'engagement médian entre les vidéos qui ont la caractéristique et les autres (en points), ou corrélation de rang ρ (de −1 à +1). « Tendances » est l'échantillon principal ; « Likées » et « Humour » servent de contrôle. Un effet n'est retenu que si p < 0,05.
B4: A. Leviers que le créateur contrôle : effet sur le taux d'engagement
B5: Levier testé | C5: Mesure | D5: Tendances | E5: p | F5: Likées | G5: p | H5: Humour | I5: p | J5: Verdict | K5: En une phrase
B6: Durée supérieure à 15 s | C6: Écart d'engagement médian (oui − non) | D6: {=(MEDIAN(IF((Donnees[Échantillon]="Tendances")*(Donnees[Plus de 15 s]="Oui"),Donnees[Engagement]))-MEDIAN(IF((Donnees[Échantillon]="Tendances")*(Donnees[Plus de 15 s]="Non"),Donnees[Engagement])))*100} -> 5.5086302 | E6: 0.024564 | F6: {=(MEDIAN(IF((Donnees[Échantillon]="Likées par @tiktok")*(Donnees[Plus de 15 s]="Oui"),Donnees[Engagement]))-MEDIAN(IF((Donnees[Échantillon]="Likées par @tiktok")*(Donnees[Plus de 15 s]="Non"),Donnees[Engagement])))*100} -> -0.36092747 | G6: 0.534884 | H6: {=(MEDIAN(IF((Donnees[Échantillon]="Humour")*(Donnees[Plus de 15 s]="Oui"),Donnees[Engagement]))-MEDIAN(IF((Donnees[Échantillon]="Humour")*(Donnees[Plus de 15 s]="Non"),Donnees[Engagement])))*100} -> 0.497501 | I6: 0.797676 | J6: Effet isolé | K6: Plus d'engagement dans les tendances (15,6 % contre 10,1 % ; 47 % de top performers contre 20 %), mais rien de tel dans les deux autres échantillons : une piste à tester, pas une règle.
B7: Durée (secondes) | C7: Corrélation de rang ρ (Spearman) | D7: {=CORREL(IF(Donnees[Échantillon]="Tendances",Donnees[Rang durée]),IF(Donnees[Échantillon]="Tendances",Donnees[Rang engagement]))} -> 0.11421644 | E7: =TDIST(ABS(D7*SQRT((100-2)/(1-D7^2))),100-2,2) -> 0.25783967 | F7: {=CORREL(IF(Donnees[Échantillon]="Likées par @tiktok",Donnees[Rang durée]),IF(Donnees[Échantillon]="Likées par @tiktok",Donnees[Rang engagement]))} -> -0.071378778 | G7: =TDIST(ABS(F7*SQRT((100-2)/(1-F7^2))),100-2,2) -> 0.48036564 | H7: {=CORREL(IF(Donnees[Échantillon]="Humour",Donnees[Rang durée]),IF(Donnees[Échantillon]="Humour",Donnees[Rang engagement]))} -> 0.21923834 | I7: =TDIST(ABS(H7*SQRT((100-2)/(1-H7^2))),100-2,2) -> 0.028411601 | J7: Effet isolé | K7: Lien faible : nul dans les tendances (ρ = +0,11) et les likées, positif seulement dans l'humour (ρ = +0,22), où les vidéos longues ont aussi moins de vues.
B8: Hashtags génériques (#fyp, #foryou, #viral…) | C8: Écart d'engagement médian (oui − non) | D8: {=(MEDIAN(IF((Donnees[Échantillon]="Tendances")*(Donnees[Hashtags génériques]="Oui"),Donnees[Engagement]))-MEDIAN(IF((Donnees[Échantillon]="Tendances")*(Donnees[Hashtags génériques]="Non"),Donnees[Engagement])))*100} -> -0.7020077 | E8: 0.319025 | F8: {=(MEDIAN(IF((Donnees[Échantillon]="Likées par @tiktok")*(Donnees[Hashtags génériques]="Oui"),Donnees[Engagement]))-MEDIAN(IF((Donnees[Échantillon]="Likées par @tiktok")*(Donnees[Hashtags génériques]="Non"),Donnees[Engagement])))*100} -> 1.2444664 | G8: 0.218662 | H8: {=(MEDIAN(IF((Donnees[Échantillon]="Humour")*(Donnees[Hashtags génériques]="Oui"),Donnees[Engagement]))-MEDIAN(IF((Donnees[Échantillon]="Humour")*(Donnees[Hashtags génériques]="Non"),Donnees[Engagement])))*100} -> -0.54052459 | I8: 0.498748 | J8: Aucun effet mesurable | K8: Aucun effet : #fyp, #foryou ou #viral ne changent pas l'engagement (écarts faibles, jamais significatifs, de signe variable).
B9: Nombre de hashtags | C9: Corrélation de rang ρ (Spearman) | D9: {=CORREL(IF(Donnees[Échantillon]="Tendances",Donnees[Rang hashtags]),IF(Donnees[Échantillon]="Tendances",Donnees[Rang engagement]))} -> -0.060577544 | E9: =TDIST(ABS(D9*SQRT((100-2)/(1-D9^2))),100-2,2) -> 0.54936657 | F9: {=CORREL(IF(Donnees[Échantillon]="Likées par @tiktok",Donnees[Rang hashtags]),IF(Donnees[Échantillon]="Likées par @tiktok",Donnees[Rang engagement]))} -> -0.015878291 | G9: =TDIST(ABS(F9*SQRT((100-2)/(1-F9^2))),100-2,2) -> 0.87540524 | H9: {=CORREL(IF(Donnees[Échantillon]="Humour",Donnees[Rang hashtags]),IF(Donnees[Échantillon]="Humour",Donnees[Rang engagement]))} -> -0.27929423 | I9: =TDIST(ABS(H9*SQRT((100-2)/(1-H9^2))),100-2,2) -> 0.0048920569 | J9: Effet isolé | K9: Aucun effet dans les tendances ni dans les likées ; négatif seulement dans l'humour (ρ = −0,28), échantillon sélectionné sur les likes : à ne pas généraliser.
B10: Longueur du texte de la légende | C10: Corrélation de rang ρ (Spearman) | D10: {=CORREL(IF(Donnees[Échantillon]="Tendances",Donnees[Rang longueur]),IF(Donnees[Échantillon]="Tendances",Donnees[Rang engagement]))} -> 0.18740377 | E10: =TDIST(ABS(D10*SQRT((100-2)/(1-D10^2))),100-2,2) -> 0.061894014 | F10: {=CORREL(IF(Donnees[Échantillon]="Likées par @tiktok",Donnees[Rang longueur]),IF(Donnees[Échantillon]="Likées par @tiktok",Donnees[Rang engagement]))} -> -0.34481943 | G10: =TDIST(ABS(F10*SQRT((100-2)/(1-F10^2))),100-2,2) -> 0.00044268269 | H10: {=CORREL(IF(Donnees[Échantillon]="Humour",Donnees[Rang longueur]),IF(Donnees[Échantillon]="Humour",Donnees[Rang engagement]))} -> 0.01008521 | I10: =TDIST(ABS(H10*SQRT((100-2)/(1-H10^2))),100-2,2) -> 0.92067249 | J10: Contradictoire | K10: Résultats contradictoires : légèrement positif dans les tendances, négatif dans les likées (ρ = −0,34) : pas de règle sur la longueur de la légende.
B11: Légende vide | C11: Écart d'engagement médian (oui − non) | D11: {=(MEDIAN(IF((Donnees[Échantillon]="Tendances")*(Donnees[Légende vide]="Oui"),Donnees[Engagement]))-MEDIAN(IF((Donnees[Échantillon]="Tendances")*(Donnees[Légende vide]="Non"),Donnees[Engagement])))*100} -> -2.487451 | E11: 0.601169 | F11: {=(MEDIAN(IF((Donnees[Échantillon]="Likées par @tiktok")*(Donnees[Légende vide]="Oui"),Donnees[Engagement]))-MEDIAN(IF((Donnees[Échantillon]="Likées par @tiktok")*(Donnees[Légende vide]="Non"),Donnees[Engagement])))*100} -> 2.1176721 | G11: 0.156448 | H11: — | J11: Aucun effet mesurable | K11: Aucun effet : une vidéo sans légende ne fait pas moins bien.
B12: Mention, duo, stitch ou réponse | C12: Écart d'engagement médian (oui − non) | D12: {=(MEDIAN(IF((Donnees[Échantillon]="Tendances")*(Donnees[Mention duo stitch]="Oui"),Donnees[Engagement]))-MEDIAN(IF((Donnees[Échantillon]="Tendances")*(Donnees[Mention duo stitch]="Non"),Donnees[Engagement])))*100} -> 0.47307548 | E12: 0.682542 | F12: {=(MEDIAN(IF((Donnees[Échantillon]="Likées par @tiktok")*(Donnees[Mention duo stitch]="Oui"),Donnees[Engagement]))-MEDIAN(IF((Donnees[Échantillon]="Likées par @tiktok")*(Donnees[Mention duo stitch]="Non"),Donnees[Engagement])))*100} -> -2.2909244 | G12: 0.161719 | H12: {=(MEDIAN(IF((Donnees[Échantillon]="Humour")*(Donnees[Mention duo stitch]="Oui"),Donnees[Engagement]))-MEDIAN(IF((Donnees[Échantillon]="Humour")*(Donnees[Mention duo stitch]="Non"),Donnees[Engagement])))*100} -> -1.0984581 | I12: 0.384554 | J12: Aucun effet mesurable | K12: Aucun effet mesurable des mentions, duos, stitchs ou réponses visibles dans la légende.
B13: Question ou appel à l'action | C13: Écart d'engagement médian (oui − non) | D13: {=(MEDIAN(IF((Donnees[Échantillon]="Tendances")*(Donnees[Question ou appel]="Oui"),Donnees[Engagement]))-MEDIAN(IF((Donnees[Échantillon]="Tendances")*(Donnees[Question ou appel]="Non"),Donnees[Engagement])))*100} -> 2.0354544 | E13: 0.065216 | F13: {=(MEDIAN(IF((Donnees[Échantillon]="Likées par @tiktok")*(Donnees[Question ou appel]="Oui"),Donnees[Engagement]))-MEDIAN(IF((Donnees[Échantillon]="Likées par @tiktok")*(Donnees[Question ou appel]="Non"),Donnees[Engagement])))*100} -> 0.33856878 | G13: 0.98598 | H13: {=(MEDIAN(IF((Donnees[Échantillon]="Humour")*(Donnees[Question ou appel]="Oui"),Donnees[Engagement]))-MEDIAN(IF((Donnees[Échantillon]="Humour")*(Donnees[Question ou appel]="Non"),Donnees[Engagement])))*100} -> -2.5666531 | I13: 0.121704 | J13: Aucun effet mesurable | K13: Pas d'effet significatif : léger plus dans les tendances (+2,0 pts, p = 0,07), moins dans l'humour.
B14: Publication le week-end | C14: Écart d'engagement médian (oui − non) | D14: {=(MEDIAN(IF((Donnees[Échantillon]="Tendances")*(Donnees[Week-end]="Oui"),Donnees[Engagement]))-MEDIAN(IF((Donnees[Échantillon]="Tendances")*(Donnees[Week-end]="Non"),Donnees[Engagement])))*100} -> 0.22260061 | E14: 0.915514 | F14: {=(MEDIAN(IF((Donnees[Échantillon]="Likées par @tiktok")*(Donnees[Week-end]="Oui"),Donnees[Engagement]))-MEDIAN(IF((Donnees[Échantillon]="Likées par @tiktok")*(Donnees[Week-end]="Non"),Donnees[Engagement])))*100} -> 2.1733856 | G14: 0.205785 | H14: {=(MEDIAN(IF((Donnees[Échantillon]="Humour")*(Donnees[Week-end]="Oui"),Donnees[Engagement]))-MEDIAN(IF((Donnees[Échantillon]="Humour")*(Donnees[Week-end]="Non"),Donnees[Engagement])))*100} -> -0.9960722 | I14: 0.574207 | J14: Aucun effet mesurable | K14: Aucun effet : publier le week-end ou en semaine revient au même.
B15: Jour de publication | C15: Écart max entre modalités | D15: =(MAX(D76:D82)-MIN(D76:D82))*100 -> 7.4498208 | E15: 0.645372 | F15: =(MAX(F76:F82)-MIN(F76:F82))*100 -> 10.913138 | G15: 0.066937 | H15: =(MAX(H76:H82)-MIN(H76:H82))*100 -> 2.0395287 | I15: 0.886935 | J15: Aucun effet mesurable | K15: Aucun jour de publication ne se détache durablement (écarts non significatifs dans les trois échantillons).
B16: Créneau horaire (UTC) | C16: Écart max entre modalités | D16: =(MAX(D85:D88)-MIN(D85:D88))*100 -> 1.1618126 | E16: 0.41431 | F16: =(MAX(F85:F88)-MIN(F85:F88))*100 -> 6.9853834 | G16: 0.19264 | H16: =(MAX(H85:H88)-MIN(H85:H88))*100 -> 4.8126691 | I16: 0.068634 | J16: Aucun effet mesurable | K16: Aucun créneau horaire ne se détache (écarts non significatifs).
B17: Sujet du contenu (thème du créateur) | C17: Écart max entre modalités | D17: =(MAX('Catégories & TreeMap'!C73:C77)-MIN('Catégories & TreeMap'!C73:C77))*100 -> 4.2214309 | E17: 0.326218 | F17: — | H17: =(MAX('Catégories & TreeMap'!D73:D77)-MIN('Catégories & TreeMap'!D73:D77))*100 -> 4.3743181 | I17: 0.392881 | J17: Aucun effet mesurable | K17: Aucun sujet ne gagne systématiquement : le classement des sujets change d'un échantillon à l'autre et les écarts ne sont pas significatifs.
B18: Son original (vs musique existante) | C18: Écart d'engagement médian (oui − non) | D18: — | F18: — | H18: {=(MEDIAN(IF((Donnees[Échantillon]="Humour")*(Donnees[Son original]="Oui"),Donnees[Engagement]))-MEDIAN(IF((Donnees[Échantillon]="Humour")*(Donnees[Son original]="Non"),Donnees[Engagement])))*100} -> -3.2739429 | I18: 0.068317 | J18: Aucun effet mesurable | K18: Léger avantage aux musiques existantes sur les sons originaux (−3,3 pts pour le son original), non significatif (p = 0,07).
B19: Stitch autorisé | C19: Écart d'engagement médian (oui − non) | D19: — | F19: — | H19: {=(MEDIAN(IF((Donnees[Échantillon]="Humour")*(Donnees[Stitch autorisé]="Oui"),Donnees[Engagement]))-MEDIAN(IF((Donnees[Échantillon]="Humour")*(Donnees[Stitch autorisé]="Non"),Donnees[Engagement])))*100} -> -0.54052459 | I19: 0.757734 | J19: Aucun effet mesurable | K19: Aucun effet du fait d'autoriser les stitchs.
B20: Vidéos publiées par le compte (régularité) | C20: Corrélation de rang ρ (Spearman) | D20: — | F20: — | H20: {=CORREL(IF(Donnees[Échantillon]="Humour",Donnees[Rang vidéos publiées]),IF(Donnees[Échantillon]="Humour",Donnees[Rang engagement]))} -> -0.15999329 | I20: =TDIST(ABS(H20*SQRT((100-2)/(1-H20^2))),100-2,2) -> 0.111817 | J20: Aucun effet mesurable | K20: Publier davantage (nombre de vidéos du compte) n'est pas associé à plus d'engagement (lien faible et non significatif).
B21: p : probabilité d'observer un tel écart par hasard. Écarts et ρ sont des formules Excel sur l'onglet Données ; les p des écarts (tests de Mann-Whitney et de Kruskal-Wallis) sont calculées par le script Python du projet. Les facteurs « son original », « stitch » et « vidéos publiées » n'existent que dans l'extrait Humour.
B23: Seule la durée se détache, et seulement dans les tendances
B24: Données du graphique (elles renvoient au tableau A)
B25: Levier | D25: Tendances | F25: Likées | H25: Humour
B26: Durée > 15 s | D26: =D6 -> 5.5086302 | F26: =F6 -> -0.36092747 | H26: =H6 -> 0.497501
B27: Hashtags #fyp… | D27: =D8 -> -0.7020077 | F27: =F8 -> 1.2444664 | H27: =H8 -> -0.54052459
B28: Légende vide | D28: =D11 -> -2.487451 | F28: =F11 -> 2.1176721 | H28: —
B29: Mention / duo | D29: =D12 -> 0.47307548 | F29: =F12 -> -2.2909244 | H29: =H12 -> -1.0984581
B30: Question / appel | D30: =D13 -> 2.0354544 | F30: =F13 -> 0.33856878 | H30: =H13 -> -2.5666531
B31: Week-end | D31: =D14 -> 0.22260061 | F31: =F14 -> 2.1733856 | H31: =H14 -> -0.9960722
B43: B. Conséquences du succès : à connaître, mais pas des leviers
B44: Variable | C44: Mesure | D44: Valeur | E44: p | F44: Statut | G44: Pourquoi ce n'est pas un levier
B45: Nombre d'abonnés | C45: ρ avec les vues (Humour) | D45: {=CORREL(IF(Donnees[Échantillon]="Humour",Donnees[Rang abonnés]),IF(Donnees[Échantillon]="Humour",Donnees[Rang vues]))} -> 0.28067579 | E45: =TDIST(ABS(D45*SQRT((100-2)/(1-D45^2))),100-2,2) -> 0.0046757515 | F45: Conséquence | G45: Le résultat d'années de succès : on ne peut pas l'« activer » pour une campagne. Lien faible avec les vues, voir l'onglet Gros comptes.
B46: Nombre d'abonnés | C46: ρ avec l'engagement (Humour) | D46: {=CORREL(IF(Donnees[Échantillon]="Humour",Donnees[Rang abonnés]),IF(Donnees[Échantillon]="Humour",Donnees[Rang engagement]))} -> -0.31479314 | E46: =TDIST(ABS(D46*SQRT((100-2)/(1-D46^2))),100-2,2) -> 0.0014234111 | F46: Conséquence | G46: Plus le compte est gros, moins son audience réagit en proportion.
B47: Likes cumulés du compte | C47: ρ avec les vues (Humour) | D47: 0.197423 | E47: 0.048973 | F47: Conséquence | G47: Somme des succès passés. Variable non transmise dans cette version (non actionnable, minimisation).
B48: Badge « vérifié » | C48: Écart d'engagement (vérifié − non) | D48: -1.3614 | E48: 0.131867 | F48: Conséquence | G48: Attribué par la plateforme aux comptes notoires. Indicateur sur une personne, non transmis dans cette version (minimisation).
B51: C. Détail : la durée
B52: Part de top performers | D52: Tendances | F52: Likées | H52: Humour
B53: 1. ≤ 10 s | D53: =AVERAGEIFS(Donnees[Top performer],Donnees[Échantillon],"Tendances",Donnees[Classe de durée],"1. ≤ 10 s") -> 0.14285714 | F53: =AVERAGEIFS(Donnees[Top performer],Donnees[Échantillon],"Likées par @tiktok",Donnees[Classe de durée],"1. ≤ 10 s") -> 0.21428571 | H53: =AVERAGEIFS(Donnees[Top performer],Donnees[Échantillon],"Humour",Donnees[Classe de durée],"1. ≤ 10 s") -> 0.15384615
B54: 2. 11-15 s | D54: =AVERAGEIFS(Donnees[Top performer],Donnees[Échantillon],"Tendances",Donnees[Classe de durée],"2. 11-15 s") -> 0.26829268 | F54: =AVERAGEIFS(Donnees[Top performer],Donnees[Échantillon],"Likées par @tiktok",Donnees[Classe de durée],"2. 11-15 s") -> 0.24324324 | H54: =AVERAGEIFS(Donnees[Top performer],Donnees[Échantillon],"Humour",Donnees[Classe de durée],"2. 11-15 s") -> 0.31578947
B55: 3. 16-30 s | D55: =AVERAGEIFS(Donnees[Top performer],Donnees[Échantillon],"Tendances",Donnees[Classe de durée],"3. 16-30 s") -> 0.66666667 | F55: =AVERAGEIFS(Donnees[Top performer],Donnees[Échantillon],"Likées par @tiktok",Donnees[Classe de durée],"3. 16-30 s") -> 0.33333333 | H55: =AVERAGEIFS(Donnees[Top performer],Donnees[Échantillon],"Humour",Donnees[Classe de durée],"3. 16-30 s") -> 0.14285714
...

Sheet Gros comptes
B1: « Les gros comptes gagneraient de toute façon » : ce que disent les données
B2: Seul l'extrait Humour (top 100 des vidéos #funny) contient le nombre d'abonnés : c'est donc sur lui que porte la réponse. Les tendances ne permettent pas de répondre.
B4: La réponse courte | I4: Chiffre | J4: Ce que mesure le chiffre
B5: Pour la portée : NON. Les comptes de plus de 8 M d'abonnés en ont 36 fois plus que ceux de moins de 1 M, mais n'obtiennent que 1,3 fois plus de vues médianes (65,0 M contre 48,4 M). | I5: =C19 -> 0.28067579 | J5: corrélation de rang abonnés ↔ vues (0 = aucun lien, 1 = lien parfait)
B6: Pour l'engagement : plutôt l'INVERSE. Sous 1 M d'abonnés, 19,1 % d'engagement médian et 43 % de top performers ; au-delà de 8 M, 13,2 % et 10 %. À vues égales, l'écart se réduit : tendance à confirmer. | I6: =C20 -> -0.31479314 | J6: corrélation de rang abonnés ↔ engagement (négative = moins d'engagement quand le compte grossit)
B7: Par abonné, les petits comptes rapportent bien plus : 112 vues par abonné (médiane) sous 1 M, contre 4,4 au-delà de 8 M. Intéressant si la rémunération suit le nombre d'abonnés. | I7: =G11/G14 -> 25.322145 | J7: rapport des vues par abonné : moins de 1 M / plus de 8 M
B9: Par taille de compte (top 100 #funny, 100 vidéos, 79 créateurs)
B10: Tranche d'abonnés | C10: Vidéos | D10: Créateurs | E10: Abonnés (médiane) | F10: Vues (médiane) | G10: Vues par abonné (médiane) | H10: Engagement (médiane) | I10: Part de top performers
B11: 1. < 1 M | C11: =COUNTIFS(Donnees[Échantillon],"Humour",Donnees[Tranche abonnés],"1. < 1 M") -> 28 | D11: {=SUM(IF((Donnees[Échantillon]="Humour")*(Donnees[Tranche abonnés]="1. < 1 M"),1/COUNTIFS(Donnees[Créateur],Donnees[Créateur],Donnees[Échantillon],"Humour")))} -> 28 | E11: {=MEDIAN(IF((Donnees[Échantillon]="Humour")*(Donnees[Tranche abonnés]="1. < 1 M"),Donnees[Abonnés]))} -> 456550 | F11: {=MEDIAN(IF((Donnees[Échantillon]="Humour")*(Donnees[Tranche abonnés]="1. < 1 M"),Donnees[Vues]))} -> 48400000 | G11: {=MEDIAN(IF((Donnees[Échantillon]="Humour")*(Donnees[Tranche abonnés]="1. < 1 M"),Donnees[Vues par abonné]))} -> 111.79581 | H11: {=MEDIAN(IF((Donnees[Échantillon]="Humour")*(Donnees[Tranche abonnés]="1. < 1 M"),Donnees[Engagement]))} -> 0.19109258 | I11: =AVERAGEIFS(Donnees[Top performer],Donnees[Échantillon],"Humour",Donnees[Tranche abonnés],"1. < 1 M") -> 0.42857143
B12: 2. 1-3 M | C12: =COUNTIFS(Donnees[Échantillon],"Humour",Donnees[Tranche abonnés],"2. 1-3 M") -> 21 | D12: {=SUM(IF((Donnees[Échantillon]="Humour")*(Donnees[Tranche abonnés]="2. 1-3 M"),1/COUNTIFS(Donnees[Créateur],Donnees[Créateur],Donnees[Échantillon],"Humour")))} -> 20 | E12: {=MEDIAN(IF((Donnees[Échantillon]="Humour")*(Donnees[Tranche abonnés]="2. 1-3 M"),Donnees[Abonnés]))} -> 1800000 | F12: {=MEDIAN(IF((Donnees[Échantillon]="Humour")*(Donnees[Tranche abonnés]="2. 1-3 M"),Donnees[Vues]))} -> 73600000 | G12: {=MEDIAN(IF((Donnees[Échantillon]="Humour")*(Donnees[Tranche abonnés]="2. 1-3 M"),Donnees[Vues par abonné]))} -> 39.277778 | H12: {=MEDIAN(IF((Donnees[Échantillon]="Humour")*(Donnees[Tranche abonnés]="2. 1-3 M"),Donnees[Engagement]))} -> 0.16583497 | I12: =AVERAGEIFS(Donnees[Top performer],Donnees[Échantillon],"Humour",Donnees[Tranche abonnés],"2. 1-3 M") -> 0.28571429
B13: 3. 3-8 M | C13: =COUNTIFS(Donnees[Échantillon],"Humour",Donnees[Tranche abonnés],"3. 3-8 M") -> 31 | D13: {=SUM(IF((Donnees[Échantillon]="Humour")*(Donnees[Tranche abonnés]="3. 3-8 M"),1/COUNTIFS(Donnees[Créateur],Donnees[Créateur],Donnees[Échantillon],"Humour")))} -> 20 | E13: {=MEDIAN(IF((Donnees[Échantillon]="Humour")*(Donnees[Tranche abonnés]="3. 3-8 M"),Donnees[Abonnés]))} -> 5200000 | F13: {=MEDIAN(IF((Donnees[Échantillon]="Humour")*(Donnees[Tranche abonnés]="3. 3-8 M"),Donnees[Vues]))} -> 53100000 | G13: {=MEDIAN(IF((Donnees[Échantillon]="Humour")*(Donnees[Tranche abonnés]="3. 3-8 M"),Donnees[Vues par abonné]))} -> 9.3157895 | H13: {=MEDIAN(IF((Donnees[Échantillon]="Humour")*(Donnees[Tranche abonnés]="3. 3-8 M"),Donnees[Engagement]))} -> 0.15494876 | I13: =AVERAGEIFS(Donnees[Top performer],Donnees[Échantillon],"Humour",Donnees[Tranche abonnés],"3. 3-8 M") -> 0.16129032
B14: 4. ≥ 8 M | C14: =COUNTIFS(Donnees[Échantillon],"Humour",Donnees[Tranche abonnés],"4. ≥ 8 M") -> 20 | D14: {=SUM(IF((Donnees[Échantillon]="Humour")*(Donnees[Tranche abonnés]="4. ≥ 8 M"),1/COUNTIFS(Donnees[Créateur],Donnees[Créateur],Donnees[Échantillon],"Humour")))} -> 11 | E14: {=MEDIAN(IF((Donnees[Échantillon]="Humour")*(Donnees[Tranche abonnés]="4. ≥ 8 M"),Donnees[Abonnés]))} -> 16450000 | F14: {=MEDIAN(IF((Donnees[Échantillon]="Humour")*(Donnees[Tranche abonnés]="4. ≥ 8 M"),Donnees[Vues]))} -> 65050000 | G14: {=MEDIAN(IF((Donnees[Échantillon]="Humour")*(Donnees[Tranche abonnés]="4. ≥ 8 M"),Donnees[Vues par abonné]))} -> 4.4149425 | H14: {=MEDIAN(IF((Donnees[Échantillon]="Humour")*(Donnees[Tranche abonnés]="4. ≥ 8 M"),Donnees[Engagement]))} -> 0.13169012 | I14: =AVERAGEIFS(Donnees[Top performer],Donnees[Échantillon],"Humour",Donnees[Tranche abonnés],"4. ≥ 8 M") -> 0.1
B15: Ensemble (Humour) | C15: =COUNTIFS(Donnees[Échantillon],"Humour") -> 100 | D15: {=SUM(IF((Donnees[Échantillon]="Humour"),1/COUNTIFS(Donnees[Créateur],Donnees[Créateur],Donnees[Échantillon],"Humour")))} -> 79 | E15: {=MEDIAN(IF((Donnees[Échantillon]="Humour"),Donnees[Abonnés]))} -> 3050000 | F15: {=MEDIAN(IF((Donnees[Échantillon]="Humour"),Donnees[Vues]))} -> 53650000 | G15: {=MEDIAN(IF((Donnees[Échantillon]="Humour"),Donnees[Vues par abonné]))} -> 23.632479 | H15: {=MEDIAN(IF((Donnees[Échantillon]="Humour"),Donnees[Engagement]))} -> 0.16348722 | I15: =AVERAGEIFS(Donnees[Top performer],Donnees[Échantillon],"Humour") -> 0.25
B17: Corrélations (ρ de Spearman)
B18: Relation | C18: ρ | D18: p | E18: n | F18: Lecture
B19: Abonnés ↔ vues (par vidéo) | C19: {=CORREL(IF(Donnees[Échantillon]="Humour",Donnees[Rang abonnés]),IF(Donnees[Échantillon]="Humour",Donnees[Rang vues]))} -> 0.28067579 | D19: =TDIST(ABS(C19*SQRT((100-2)/(1-C19^2))),100-2,2) -> 0.0046757515 | E19: 100 | F19: Lien positif mais faible : la taille du compte n'explique qu'une petite partie de la portée.
B20: Abonnés ↔ engagement (par vidéo) | C20: {=CORREL(IF(Donnees[Échantillon]="Humour",Donnees[Rang abonnés]),IF(Donnees[Échantillon]="Humour",Donnees[Rang engagement]))} -> -0.31479314 | D20: =TDIST(ABS(C20*SQRT((100-2)/(1-C20^2))),100-2,2) -> 0.0014234111 | E20: 100 | F20: Plus le compte est gros, moins son audience réagit en proportion.
B21: Abonnés ↔ vues médianes (par créateur) | C21: 0.247049 | D21: 0.028166 | E21: 79 | F21: Même conclusion en ne comptant qu'une fois chaque créateur (calcul Python : médiane par créateur).
B22: Abonnés ↔ engagement, à vues égales (partielle) | C22: -0.154053 | D22: 0.12789768 | E22: 100 | F22: Une fois les vues neutralisées, le lien s'affaiblit et n'est plus significatif (calcul Python).
B23: Vues ↔ engagement (dans cet extrait) | C23: {=CORREL(IF(Donnees[Échantillon]="Humour",Donnees[Rang vues]),IF(Donnees[Échantillon]="Humour",Donnees[Rang engagement]))} -> -0.82013478 | D23: =TDIST(ABS(C23*SQRT((100-2)/(1-C23^2))),100-2,2) -> 1.6855104e-25 | E23: 100 | F23: Très négatif : effet de la sélection sur les likes (≥ 6,8 M), pas un comportement du public. D'où l'usage des vues pour juger les gros comptes.
B25: Ce que les données permettent de répondre | F25: Ce qu'elles ne permettent pas de dire
B26: • Parmi les vidéos qui ont percé, la taille du compte n'explique qu'une petite partie de la portée (ρ = +0,28). | F26: • La probabilité de percer : les petits comptes qui n'ont pas percé ne sont pas dans les données (biais du survivant).
B27: • Des comptes de moins de 1 M d'abonnés atteignent des dizaines de millions de vues : la portée ne dépend pas que du nombre d'abonnés. | F27: • La causalité : les abonnés sont comptés en août 2021, après les vidéos ; le succès a pu créer les abonnés.
B28: • L'engagement relatif baisse avec la taille du compte (19,1 % → 13,2 %). | F28: • La situation dans les tendances (abonnés absents de l'extrait) ou hors du registre humoristique.
B29: • Le résultat tient en comptant chaque créateur une seule fois (ρ = +0,25 sur 79 créateurs). | F29: • Si l'écart d'engagement tient à vues égales : il s'affaiblit (ρ partiel = −0,15) et n'est plus significatif.
B31: 36 fois plus d'abonnés, 1,3 fois plus de vues
B57: Tableau croisé dynamique : vidéos, top performers et engagement moyen par tranche (filtre : Humour ; se met à jour à l'ouverture)
B59: Échantillon | C59: Humour
C61: Valeurs
B62: Tranche d'abonnés | C62: Vidéos | D62: Part de top performers | E62: Engagement moyen
B63: 1. < 1 M | C63: 28 | D63: 0.42857143 | E63: 0.18807505
B64: 2. 1-3 M | C64: 21 | D64: 0.28571429 | E64: 0.14912614
B65: 3. 3-8 M | C65: 31 | D65: 0.16129032 | E65: 0.16056141
B66: 4. ≥ 8 M | C66: 20 | D66: 0.1 | E66: 0.1445914
B67: Total | C67: 100 | D67: 0.25 | E67: 0.16266982

Sheet Catégories & TreeMap
B1: Qui se distingue ? Sujets de contenu, leaders et TreeMap
B2: Catégories : 5 sujets déduits des hashtags et légendes, attribués à chaque créateur. Leader = meilleur taux d'engagement, rapporté à la médiane de son échantillon (indice), parmi les créateurs dont la portée médiane atteint au moins la médiane de leur échantillon. Périmètre : Tendances + Humour.
B4: A. Les 5 sujets de contenu
B5: Sujet | C5: Créateurs | D5: Vidéos | E5: Vues cumulées | F5: Part des vues | G5: Engagement médian | H5: Part de top performers | I5: Lecture
B6: Animaux | C6: {=SUM(IF((Donnees[Thème]="Animaux")*(Donnees[Échantillon]<>"Likées par @tiktok"),1/COUNTIFS(Donnees[Créateur],Donnees[Créateur],Donnees[Échantillon],"<>Likées par @tiktok")))} -> 33 | D6: =COUNTIFS(Donnees[Thème],"Animaux",Donnees[Échantillon],"<>Likées par @tiktok",Donnees[Compté dans les cumuls],"Oui") -> 34 | E6: =SUMIFS(Donnees[Vues],Donnees[Thème],"Animaux",Donnees[Échantillon],"<>Likées par @tiktok",Donnees[Compté dans les cumuls],"Oui") -> 1664891300 | F6: =E6/SUM($E$6:$E$10) -> 0.18257807 | G6: {=MEDIAN(IF((Donnees[Thème]="Animaux")*(Donnees[Échantillon]<>"Likées par @tiktok")*(Donnees[Compté dans les cumuls]="Oui"),Donnees[Engagement]))} -> 0.12163462 | H6: =AVERAGEIFS(Donnees[Top performer],Donnees[Thème],"Animaux",Donnees[Échantillon],"<>Likées par @tiktok",Donnees[Compté dans les cumuls],"Oui") -> 0.23529412 | I6: Contenus d'animaux : portée solide, engagement moyen.
B7: Famille & enfants | C7: {=SUM(IF((Donnees[Thème]="Famille & enfants")*(Donnees[Échantillon]<>"Likées par @tiktok"),1/COUNTIFS(Donnees[Créateur],Donnees[Créateur],Donnees[Échantillon],"<>Likées par @tiktok")))} -> 24 | D7: =COUNTIFS(Donnees[Thème],"Famille & enfants",Donnees[Échantillon],"<>Likées par @tiktok",Donnees[Compté dans les cumuls],"Oui") -> 30 | E7: =SUMIFS(Donnees[Vues],Donnees[Thème],"Famille & enfants",Donnees[Échantillon],"<>Likées par @tiktok",Donnees[Compté dans les cumuls],"Oui") -> 1356700000 | F7: =E7/SUM($E$6:$E$10) -> 0.14878069 | G7: {=MEDIAN(IF((Donnees[Thème]="Famille & enfants")*(Donnees[Échantillon]<>"Likées par @tiktok")*(Donnees[Compté dans les cumuls]="Oui"),Donnees[Engagement]))} -> 0.15176603 | H7: =AVERAGEIFS(Donnees[Top performer],Donnees[Thème],"Famille & enfants",Donnees[Échantillon],"<>Likées par @tiktok",Donnees[Compté dans les cumuls],"Oui") -> 0.23333333 | I7: Engagement élevé ; présence fréquente de mineurs (voir vigilance).
B8: Humour & sketchs | C8: {=SUM(IF((Donnees[Thème]="Humour & sketchs")*(Donnees[Échantillon]<>"Likées par @tiktok"),1/COUNTIFS(Donnees[Créateur],Donnees[Créateur],Donnees[Échantillon],"<>Likées par @tiktok")))} -> 51 | D8: =COUNTIFS(Donnees[Thème],"Humour & sketchs",Donnees[Échantillon],"<>Likées par @tiktok",Donnees[Compté dans les cumuls],"Oui") -> 65 | E8: =SUMIFS(Donnees[Vues],Donnees[Thème],"Humour & sketchs",Donnees[Échantillon],"<>Likées par @tiktok",Donnees[Compté dans les cumuls],"Oui") -> 3682637500 | F8: =E8/SUM($E$6:$E$10) -> 0.4038515 | G8: {=MEDIAN(IF((Donnees[Thème]="Humour & sketchs")*(Donnees[Échantillon]<>"Likées par @tiktok")*(Donnees[Compté dans les cumuls]="Oui"),Donnees[Engagement]))} -> 0.15936128 | H8: =AVERAGEIFS(Donnees[Top performer],Donnees[Thème],"Humour & sketchs",Donnees[Échantillon],"<>Likées par @tiktok",Donnees[Compté dans les cumuls],"Oui") -> 0.24615385 | I8: Le plus gros volume de vues, porté par l'échantillon #funny.
B9: Lifestyle, musique & sport | C9: {=SUM(IF((Donnees[Thème]="Lifestyle, musique & sport")*(Donnees[Échantillon]<>"Likées par @tiktok"),1/COUNTIFS(Donnees[Créateur],Donnees[Créateur],Donnees[Échantillon],"<>Likées par @tiktok")))} -> 26 | D9: =COUNTIFS(Donnees[Thème],"Lifestyle, musique & sport",Donnees[Échantillon],"<>Likées par @tiktok",Donnees[Compté dans les cumuls],"Oui") -> 33 | E9: =SUMIFS(Donnees[Vues],Donnees[Thème],"Lifestyle, musique & sport",Donnees[Échantillon],"<>Likées par @tiktok",Donnees[Compté dans les cumuls],"Oui") -> 1648700000 | F9: =E9/SUM($E$6:$E$10) -> 0.18080248 | G9: {=MEDIAN(IF((Donnees[Thème]="Lifestyle, musique & sport")*(Donnees[Échantillon]<>"Likées par @tiktok")*(Donnees[Compté dans les cumuls]="Oui"),Donnees[Engagement]))} -> 0.13837275 | H9: =AVERAGEIFS(Donnees[Top performer],Donnees[Thème],"Lifestyle, musique & sport",Donnees[Échantillon],"<>Likées par @tiktok",Donnees[Compté dans les cumuls],"Oui") -> 0.3030303 | I9: Sujet hétérogène (musique, sport, cuisine, beauté…).
B10: Sujet non déclaré | C10: {=SUM(IF((Donnees[Thème]="Sujet non déclaré")*(Donnees[Échantillon]<>"Likées par @tiktok"),1/COUNTIFS(Donnees[Créateur],Donnees[Créateur],Donnees[Échantillon],"<>Likées par @tiktok")))} -> 24 | D10: =COUNTIFS(Donnees[Thème],"Sujet non déclaré",Donnees[Échantillon],"<>Likées par @tiktok",Donnees[Compté dans les cumuls],"Oui") -> 37 | E10: =SUMIFS(Donnees[Vues],Donnees[Thème],"Sujet non déclaré",Donnees[Échantillon],"<>Likées par @tiktok",Donnees[Compté dans les cumuls],"Oui") -> 765862300 | F10: =E10/SUM($E$6:$E$10) -> 0.083987262 | G10: {=MEDIAN(IF((Donnees[Thème]="Sujet non déclaré")*(Donnees[Échantillon]<>"Likées par @tiktok")*(Donnees[Compté dans les cumuls]="Oui"),Donnees[Engagement]))} -> 0.10046012 | H10: =AVERAGEIFS(Donnees[Top performer],Donnees[Thème],"Sujet non déclaré",Donnees[Échantillon],"<>Likées par @tiktok",Donnees[Compté dans les cumuls],"Oui") -> 0.24324324 | I10: Légende vide ou sans mot-clé : souvent des comptes de personnalités.
B11: Concentration : 10 % des créateurs (16 sur 158) captent 42 % des vues cumulées (calcul du script Python, sur les vues cumulées par créateur). Aucun sujet ne se détache nettement en engagement : voir le tableau E et l'onglet Facteurs.
B14: B. Leaders par sujet : meilleur engagement, à portée au moins médiane
B15: Sujet | C15: Créateur | D15: Rang | E15: Échantillon | F15: Vidéos | G15: Vues médianes | H15: Engagement médian | I15: Indice d'engagement | J15: Abonnés | K15: Pourquoi
B16: Animaux | C16: @www9781 | D16: 1 | E16: Tendances | F16: =COUNTIFS(Donnees[Créateur],"@www9781",Donnees[Échantillon],"Tendances") -> 1 | G16: {=MEDIAN(IF((Donnees[Créateur]="@www9781")*(Donnees[Échantillon]="Tendances"),Donnees[Vues]))} -> 11400000 | H16: {=MEDIAN(IF((Donnees[Créateur]="@www9781")*(Donnees[Échantillon]="Tendances"),Donnees[Engagement]))} -> 0.19607895 | I16: =H16/VLOOKUP(E16,'Méthode & limites'!$B$9:$D$11,3,FALSE) -> 1.83643 | J16: — | K16: engagement 19,6 % = 1,8× la médiane de son échantillon ; 11,4 M de vues médianes
B17: Animaux | C17: @thepetcollective | D17: 2 | E17: Tendances | F17: =COUNTIFS(Donnees[Créateur],"@thepetcollective",Donnees[Échantillon],"Tendances") -> 1 | G17: {=MEDIAN(IF((Donnees[Créateur]="@thepetcollective")*(Donnees[Échantillon]="Tendances"),Donnees[Vues]))} -> 13200000 | H17: {=MEDIAN(IF((Donnees[Créateur]="@thepetcollective")*(Donnees[Échantillon]="Tendances"),Donnees[Engagement]))} -> 0.17941667 | I17: =H17/VLOOKUP(E17,'Méthode & limites'!$B$9:$D$11,3,FALSE) -> 1.6803749 | J17: — | K17: engagement 17,9 % = 1,7× la médiane de son échantillon ; 13,2 M de vues médianes
B18: Animaux | C18: @ttmmff100 | D18: 3 | E18: Humour | F18: =COUNTIFS(Donnees[Créateur],"@ttmmff100",Donnees[Échantillon],"Humour") -> 1 | G18: {=MEDIAN(IF((Donnees[Créateur]="@ttmmff100")*(Donnees[Échantillon]="Humour"),Donnees[Vues]))} -> 59400000 | H18: {=MEDIAN(IF((Donnees[Créateur]="@ttmmff100")*(Donnees[Échantillon]="Humour"),Donnees[Engagement]))} -> 0.23341077 | I18: =H18/VLOOKUP(E18,'Méthode & limites'!$B$9:$D$11,3,FALSE) -> 1.4277004 | J18: =AVERAGEIFS(Donnees[Abonnés],Donnees[Créateur],"@ttmmff100",Donnees[Échantillon],"Humour") -> 168400 | K18: engagement 23,3 % = 1,4× la médiane de son échantillon ; 59,4 M de vues médianes ; 0,2 M d'abonnés
B19: Famille & enfants | C19: @hayndkay_mom | D19: 1 | E19: Tendances | F19: =COUNTIFS(Donnees[Créateur],"@hayndkay_mom",Donnees[Échantillon],"Tendances") -> 1 | G19: {=MEDIAN(IF((Donnees[Créateur]="@hayndkay_mom")*(Donnees[Échantillon]="Tendances"),Donnees[Vues]))} -> 33500000 | H19: {=MEDIAN(IF((Donnees[Créateur]="@hayndkay_mom")*(Donnees[Échantillon]="Tendances"),Donnees[Engagement]))} -> 0.17048358 | I19: =H19/VLOOKUP(E19,'Méthode & limites'!$B$9:$D$11,3,FALSE) -> 1.5967097 | J19: — | K19: engagement 17,0 % = 1,6× la médiane de son échantillon ; 33,5 M de vues médianes
B20: Famille & enfants | C20: @relaxedbryan | D20: 2 | E20: Tendances | F20: =COUNTIFS(Donnees[Créateur],"@relaxedbryan",Donnees[Échantillon],"Tendances") -> 1 | G20: {=MEDIAN(IF((Donnees[Créateur]="@relaxedbryan")*(Donnees[Échantillon]="Tendances"),Donnees[Vues]))} -> 25000000 | H20: {=MEDIAN(IF((Donnees[Créateur]="@relaxedbryan")*(Donnees[Échantillon]="Tendances"),Donnees[Engagement]))} -> 0.166176 | I20: =H20/VLOOKUP(E20,'Méthode & limites'!$B$9:$D$11,3,FALSE) -> 1.5563659 | J20: — | K20: engagement 16,6 % = 1,6× la médiane de son échantillon ; 25,0 M de vues médianes
B21: Famille & enfants | C21: @momma_mandy_plus7 | D21: 3 | E21: Tendances | F21: =COUNTIFS(Donnees[Créateur],"@momma_mandy_plus7",Donnees[Échantillon],"Tendances") -> 1 | G21: {=MEDIAN(IF((Donnees[Créateur]="@momma_mandy_plus7")*(Donnees[Échantillon]="Tendances"),Donnees[Vues]))} -> 32200000 | H21: {=MEDIAN(IF((Donnees[Créateur]="@momma_mandy_plus7")*(Donnees[Échantillon]="Tendances"),Donnees[Engagement]))} -> 0.16485404 | I21: =H21/VLOOKUP(E21,'Méthode & limites'!$B$9:$D$11,3,FALSE) -> 1.5439847 | J21: — | K21: engagement 16,5 % = 1,5× la médiane de son échantillon ; 32,2 M de vues médianes
B22: Humour & sketchs | C22: @hassankhadair | D22: 1 | E22: Tendances | F22: =COUNTIFS(Donnees[Créateur],"@hassankhadair",Donnees[Échantillon],"Tendances") -> 1 | G22: {=MEDIAN(IF((Donnees[Créateur]="@hassankhadair")*(Donnees[Échantillon]="Tendances"),Donnees[Vues]))} -> 106000000 | H22: {=MEDIAN(IF((Donnees[Créateur]="@hassankhadair")*(Donnees[Échantillon]="Tendances"),Donnees[Engagement]))} -> 0.14754811 | I22: =H22/VLOOKUP(E22,'Méthode & limites'!$B$9:$D$11,3,FALSE) -> 1.3819015 | J22: — | K22: engagement 14,8 % = 1,4× la médiane de son échantillon ; 106,0 M de vues médianes
B23: Humour & sketchs | C23: @khaby.lame | D23: 2 | E23: Tendances | F23: =COUNTIFS(Donnees[Créateur],"@khaby.lame",Donnees[Échantillon],"Tendances") -> 1 | G23: {=MEDIAN(IF((Donnees[Créateur]="@khaby.lame")*(Donnees[Échantillon]="Tendances"),Donnees[Vues]))} -> 84500000 | H23: {=MEDIAN(IF((Donnees[Créateur]="@khaby.lame")*(Donnees[Échantillon]="Tendances"),Donnees[Engagement]))} -> 0.1441645 | I23: =H23/VLOOKUP(E23,'Méthode & limites'!$B$9:$D$11,3,FALSE) -> 1.3502113 | J23: — | K23: engagement 14,4 % = 1,4× la médiane de son échantillon ; 84,5 M de vues médianes
B24: Humour & sketchs | C24: @crinka11 | D24: 3 | E24: Humour | F24: =COUNTIFS(Donnees[Créateur],"@crinka11",Donnees[Échantillon],"Humour") -> 1 | G24: {=MEDIAN(IF((Donnees[Créateur]="@crinka11")*(Donnees[Échantillon]="Humour"),Donnees[Vues]))} -> 73600000 | H24: {=MEDIAN(IF((Donnees[Créateur]="@crinka11")*(Donnees[Échantillon]="Humour"),Donnees[Engagement]))} -> 0.20872554 | I24: =H24/VLOOKUP(E24,'Méthode & limites'!$B$9:$D$11,3,FALSE) -> 1.2767086 | J24: =AVERAGEIFS(Donnees[Abonnés],Donnees[Créateur],"@crinka11",Donnees[Échantillon],"Humour") -> 1300000 | K24: engagement 20,9 % = 1,3× la médiane de son échantillon ; 73,6 M de vues médianes ; 1,3 M d'abonnés
B25: Lifestyle, musique & sport | C25: @bts_official_bighit | D25: 1 | E25: Tendances | F25: =COUNTIFS(Donnees[Créateur],"@bts_official_bighit",Donnees[Échantillon],"Tendances") -> 2 | G25: {=MEDIAN(IF((Donnees[Créateur]="@bts_official_bighit")*(Donnees[Échantillon]="Tendances"),Donnees[Vues]))} -> 13350000 | H25: {=MEDIAN(IF((Donnees[Créateur]="@bts_official_bighit")*(Donnees[Échantillon]="Tendances"),Donnees[Engagement]))} -> 0.37024733 | I25: =H25/VLOOKUP(E25,'Méthode & limites'!$B$9:$D$11,3,FALSE) -> 3.4676508 | J25: — | K25: engagement 37,0 % = 3,5× la médiane de son échantillon ; 13,3 M de vues médianes ; 2 vidéos dans l'échantillon (régularité)
B26: Lifestyle, musique & sport | C26: @miakhalifa | D26: 2 | E26: Tendances | F26: =COUNTIFS(Donnees[Créateur],"@miakhalifa",Donnees[Échantillon],"Tendances") -> 1 | G26: {=MEDIAN(IF((Donnees[Créateur]="@miakhalifa")*(Donnees[Échantillon]="Tendances"),Donnees[Vues]))} -> 24900000 | H26: {=MEDIAN(IF((Donnees[Créateur]="@miakhalifa")*(Donnees[Échantillon]="Tendances"),Donnees[Engagement]))} -> 0.16186747 | I26: =H26/VLOOKUP(E26,'Méthode & limites'!$B$9:$D$11,3,FALSE) -> 1.5160132 | J26: — | K26: engagement 16,2 % = 1,5× la médiane de son échantillon ; 24,9 M de vues médianes
B27: Lifestyle, musique & sport | C27: @lights.are.off | D27: 3 | E27: Tendances | F27: =COUNTIFS(Donnees[Créateur],"@lights.are.off",Donnees[Échantillon],"Tendances") -> 1 | G27: {=MEDIAN(IF((Donnees[Créateur]="@lights.are.off")*(Donnees[Échantillon]="Tendances"),Donnees[Vues]))} -> 38200000 | H27: {=MEDIAN(IF((Donnees[Créateur]="@lights.are.off")*(Donnees[Échantillon]="Tendances"),Donnees[Engagement]))} -> 0.15597906 | I27: =H27/VLOOKUP(E27,'Méthode & limites'!$B$9:$D$11,3,FALSE) -> 1.4608637 | J27: — | K27: engagement 15,6 % = 1,5× la médiane de son échantillon ; 38,2 M de vues médianes
B28: Sujet non déclaré | C28: @roses_are_rosie | D28: 1 | E28: Tendances | F28: =COUNTIFS(Donnees[Créateur],"@roses_are_rosie",Donnees[Échantillon],"Tendances") -> 3 | G28: {=MEDIAN(IF((Donnees[Créateur]="@roses_are_rosie")*(Donnees[Échantillon]="Tendances"),Donnees[Vues]))} -> 25200000 | H28: {=MEDIAN(IF((Donnees[Créateur]="@roses_are_rosie")*(Donnees[Échantillon]="Tendances"),Donnees[Engagement]))} -> 0.2530412 | I28: =H28/VLOOKUP(E28,'Méthode & limites'!$B$9:$D$11,3,FALSE) -> 2.3699253 | J28: — | K28: engagement 25,3 % = 2,4× la médiane de son échantillon ; 25,2 M de vues médianes ; 3 vidéos dans l'échantillon (régularité)
B29: Sujet non déclaré | C29: @gagesmellslikecabbage | D29: 2 | E29: Tendances | F29: =COUNTIFS(Donnees[Créateur],"@gagesmellslikecabbage",Donnees[Échantillon],"Tendances") -> 1 | G29: {=MEDIAN(IF((Donnees[Créateur]="@gagesmellslikecabbage")*(Donnees[Échantillon]="Tendances"),Donnees[Vues]))} -> 14100000 | H29: {=MEDIAN(IF((Donnees[Créateur]="@gagesmellslikecabbage")*(Donnees[Échantillon]="Tendances"),Donnees[Engagement]))} -> 0.23800709 | I29: =H29/VLOOKUP(E29,'Méthode & limites'!$B$9:$D$11,3,FALSE) -> 2.2291193 | J29: — | K29: engagement 23,8 % = 2,2× la médiane de son échantillon ; 14,1 M de vues médianes
B30: Sujet non déclaré | C30: @user4350486101671 | D30: 3 | E30: Tendances | F30: =COUNTIFS(Donnees[Créateur],"@user4350486101671",Donnees[Échantillon],"Tendances") -> 1 | G30: {=MEDIAN(IF((Donnees[Créateur]="@user4350486101671")*(Donnees[Échantillon]="Tendances"),Donnees[Vues]))} -> 50500000 | H30: {=MEDIAN(IF((Donnees[Créateur]="@user4350486101671")*(Donnees[Échantillon]="Tendances"),Donnees[Engagement]))} -> 0.19853861 | I30: =H30/VLOOKUP(E30,'Méthode & limites'!$B$9:$D$11,3,FALSE) -> 1.8594667 | J30: — | K30: engagement 19,9 % = 1,9× la médiane de son échantillon ; 50,5 M de vues médianes
B32: C. Leaders de portée : le plus de vues cumulées par sujet
B33: Sujet | C33: Créateur | D33: Vidéos | E33: Vues cumulées | F33: À noter
B34: Animaux | C34: @funnyvids2k21 | D34: =COUNTIFS(Donnees[Créateur],"@funnyvids2k21",Donnees[Échantillon],"<>Likées par @tiktok",Donnees[Compté dans les cumuls],"Oui") -> 2 | E34: =SUMIFS(Donnees[Vues],Donnees[Créateur],"@funnyvids2k21",Donnees[Échantillon],"<>Likées par @tiktok",Donnees[Compté dans les cumuls],"Oui") -> 310100000 | F34: Portée la plus forte du sujet ; engagement médian 11,7 % (à comparer avec les leaders d'engagement).
B35: Famille & enfants | C35: @mercuri_88 | D35: =COUNTIFS(Donnees[Créateur],"@mercuri_88",Donnees[Échantillon],"<>Likées par @tiktok",Donnees[Compté dans les cumuls],"Oui") -> 3 | E35: =SUMIFS(Donnees[Vues],Donnees[Créateur],"@mercuri_88",Donnees[Échantillon],"<>Likées par @tiktok",Donnees[Compté dans les cumuls],"Oui") -> 215200000 | F35: Portée la plus forte du sujet ; engagement médian 13,4 % (à comparer avec les leaders d'engagement).
B36: Humour & sketchs | C36: @samuelgrubbs | D36: =COUNTIFS(Donnees[Créateur],"@samuelgrubbs",Donnees[Échantillon],"<>Likées par @tiktok",Donnees[Compté dans les cumuls],"Oui") -> 8 | E36: =SUMIFS(Donnees[Vues],Donnees[Créateur],"@samuelgrubbs",Donnees[Échantillon],"<>Likées par @tiktok",Donnees[Compté dans les cumuls],"Oui") -> 616200000 | F36: Portée la plus forte du sujet ; engagement médian 15,5 % (à comparer avec les leaders d'engagement).
B37: Lifestyle, musique & sport | C37: @pimplepom | D37: =COUNTIFS(Donnees[Créateur],"@pimplepom",Donnees[Échantillon],"<>Likées par @tiktok",Donnees[Compté dans les cumuls],"Oui") -> 1 | E37: =SUMIFS(Donnees[Vues],Donnees[Créateur],"@pimplepom",Donnees[Échantillon],"<>Likées par @tiktok",Donnees[Compté dans les cumuls],"Oui") -> 200200000 | F37: Portée la plus forte du sujet ; engagement médian 3,1 % (à comparer avec les leaders d'engagement).
B38: Sujet non déclaré | C38: @cacha.7.griselda | D38: =COUNTIFS(Donnees[Créateur],"@cacha.7.griselda",Donnees[Échantillon],"<>Likées par @tiktok",Donnees[Compté dans les cumuls],"Oui") -> 1 | E38: =SUMIFS(Donnees[Vues],Donnees[Créateur],"@cacha.7.griselda",Donnees[Échantillon],"<>Likées par @tiktok",Donnees[Compté dans les cumuls],"Oui") -> 222300000 | F38: Portée la plus forte du sujet ; engagement médian 14,2 % (à comparer avec les leaders d'engagement).
B40: D. TreeMap : qui capte les vues ?
B41: Lecture : chaque tuile est un créateur ; plus elle est grande, plus il a cumulé de vues (Tendances + Humour). La couleur indique le sujet du créateur. Les créateurs non retenus sont regroupés par sujet (« Autres créateurs »). La taille dit la portée, la couleur dit le sujet : deux informations différentes.
B42: Sujet | C42: Tuile | D42: Vues cumulées
B43: Animaux | C43: @funnyvids2k21 | D43: =SUMIFS(Donnees[Vues],Donnees[Créateur],"@funnyvids2k21",Donnees[Échantillon],"<>Likées par @tiktok",Donnees[Compté dans les cumuls],"Oui") -> 310100000
B44: Animaux | C44: @ttmmff100 | D44: =SUMIFS(Donnees[Vues],Donnees[Créateur],"@ttmmff100",Donnees[Échantillon],"<>Likées par @tiktok",Donnees[Compté dans les cumuls],"Oui") -> 59400000
B45: Animaux | C45: @thepetcollective | D45: =SUMIFS(Donnees[Vues],Donnees[Créateur],"@thepetcollective",Donnees[Échantillon],"<>Likées par @tiktok",Donnees[Compté dans les cumuls],"Oui") -> 13200000
...

Sheet Méthode & limites
B1: Méthode, sources et limites
B2: Comment les chiffres de ce classeur ont été obtenus, ce qu'ils valent, et comment les données personnelles ont été traitées. Toutes les valeurs sont recalculées par des formules à partir de l'onglet Données, sauf mention contraire.
B4: 1. Définition du succès
B5: Question du client : qu'est-ce qui distingue les contenus et les créateurs TikTok les plus performants ? Mesure retenue : le TAUX D'ENGAGEMENT = (likes + commentaires + partages) ÷ vues, c'est-à-dire la part des personnes touchées qui réagissent activement.
B6: Pourquoi : (1) c'est la réaction du public qu'achète une marque, pas seulement l'affichage ; (2) c'est un ratio : il ne favorise pas mécaniquement les gros comptes ni les vidéos en ligne depuis plus longtemps (dans les tendances, l'âge d'une vidéo est lié à ses vues, ρ = +0,24, mais pas à son engagement, ρ = −0,15, non significatif) ; (3) dans les tendances, l'engagement va de pair avec la portée (ρ vues–engagement = +0,21). La portée (vues) est toujours affichée à côté.
B7: TOP PERFORMERS = le quart supérieur (75e centile) du taux d'engagement, calculé séparément dans chaque échantillon, car les niveaux d'engagement diffèrent selon la façon dont l'échantillon a été constitué. Ces seuils alimentent la colonne « Top performer » de l'onglet Données.
B8: Échantillon | C8: Seuil top performers (75e centile) | D8: Engagement médian | E8: Vidéos | F8: Vues médianes | G8: Créateurs distincts
B9: Tendances | C9: {=PERCENTILE(IF(Donnees[Échantillon]="Tendances",Donnees[Engagement]),0.75)} -> 0.15577896 | D9: {=MEDIAN(IF((Donnees[Échantillon]="Tendances"),Donnees[Engagement]))} -> 0.10677181 | E9: =COUNTIFS(Donnees[Échantillon],"Tendances") -> 100 | F9: {=MEDIAN(IF((Donnees[Échantillon]="Tendances"),Donnees[Vues]))} -> 10400000 | G9: {=SUM(IF(Donnees[Échantillon]="Tendances",1/COUNTIFS(Donnees[Créateur],Donnees[Créateur],Donnees[Échantillon],"Tendances")))} -> 84
B10: Likées par @tiktok | C10: {=PERCENTILE(IF(Donnees[Échantillon]="Likées par @tiktok",Donnees[Engagement]),0.75)} -> 0.24260066 | D10: {=MEDIAN(IF((Donnees[Échantillon]="Likées par @tiktok"),Donnees[Engagement]))} -> 0.18322882 | E10: =COUNTIFS(Donnees[Échantillon],"Likées par @tiktok") -> 100 | F10: {=MEDIAN(IF((Donnees[Échantillon]="Likées par @tiktok"),Donnees[Vues]))} -> 5700000 | G10: {=SUM(IF(Donnees[Échantillon]="Likées par @tiktok",1/COUNTIFS(Donnees[Créateur],Donnees[Créateur],Donnees[Échantillon],"Likées par @tiktok")))} -> 92
B11: Humour | C11: {=PERCENTILE(IF(Donnees[Échantillon]="Humour",Donnees[Engagement]),0.75)} -> 0.20452412 | D11: {=MEDIAN(IF((Donnees[Échantillon]="Humour"),Donnees[Engagement]))} -> 0.16348722 | E11: =COUNTIFS(Donnees[Échantillon],"Humour") -> 100 | F11: {=MEDIAN(IF((Donnees[Échantillon]="Humour"),Donnees[Vues]))} -> 53650000 | G11: {=SUM(IF(Donnees[Échantillon]="Humour",1/COUNTIFS(Donnees[Créateur],Donnees[Créateur],Donnees[Échantillon],"Humour")))} -> 79
B13: Limite de cette définition : l'échantillon Humour ne contient que des vidéos à plus de 6,8 M de likes (top 100 du hashtag, trié par likes). À likes presque constants, l'engagement y baisse mécaniquement quand les vues montent (ρ vues–engagement = −0,82). Cet échantillon sert donc surtout à répondre à la question des gros comptes, avec les vues et les vues par abonné.
B15: 2. Extraits utilisés et écartés
B16: Extrait | C16: Contenu | D16: Publications | E16: Collecte (estimée) | F16: Rôle | G16: Pourquoi
B17: trending_videos.csv | C17: 100 vidéos, 84 créateurs | D17: 27/05 → 24/08/2021 | E17: ≈ 25/08/2021 | F17: Principal | G17: Vidéos mises en avant par l'algorithme, les plus récentes : la meilleure image de « ce qui performe ». Contient les 4 métriques et les leviers (durée, légende, date). Ne contient pas les abonnés.
B18: tiktok_funny_hashtag_videos.csv | C18: 100 vidéos, 79 créateurs | D18: 04/10/2019 → 31/07/2021 | E18: ≈ 25/08/2021 | F18: Contrôle + gros comptes | G18: Seul extrait avec les abonnés et la musique. Biais : un seul registre (#funny) et top 100 trié par likes (≥ 6,8 M).
B19: tiktok_collected_liked_videos.csv | C19: 100 vidéos, 92 créateurs | D19: 10/02 → 21/08/2021 | E19: ≈ 22/08/2021 | F19: Contrôle | G19: Même format que les tendances, mais sélection éditoriale du compte officiel (célébrités, marques) : sert à vérifier qu'un effet se répète.
B20: trending_authors.csv | C20: 100 lignes, 92 auteurs (8 doublons) | D20: — | E20: ≈ 23/08/2021 | F20: Écarté | G20: Aucune métrique de performance, surtout des données personnelles (bios avec e-mails, téléphones, comptes de paiement). Seul apport possible : le badge vérifié, conséquence du succès et non levier. Le garder contredirait la minimisation (RGPD).
B21: tiktok_collected_videos.csv | C21: 100 vidéos, 1 compte | D21: 09/09/2019 → 10/08/2021 | E21: ≥ 10/08/2021 | F21: Écarté | G21: Vidéos du compte officiel @tiktok : un acteur institutionnel unique qui promeut la plateforme, pas un créateur qu'une marque peut recruter.
B23: 3. Préparation des données
B24: • Les 3 extraits retenus sont fusionnés en une table de 300 vidéos (onglet Données), colonnes renommées et uniformisées. Les CSV bruts ne sont jamais modifiés ; tout est reproductible avec les scripts du projet.
B25: • Doublons : aucune vidéo en double dans un même extrait. Une vidéo figure à la fois dans Tendances et Humour (chiffres quasi identiques) : elle reste dans chaque échantillon mais n'est comptée qu'une fois dans les vues cumulées (colonne « Compté dans les cumuls »).
B26: • Valeurs manquantes : 19 légendes vides (13 tendances, 6 likées), traitées comme une variable (« Légende vide ») ; 3 vidéos à 0 commentaire (commentaires sans doute désactivés), conservées.
B27: • Dates : la date de publication est encodée dans l'identifiant de chaque vidéo (vérifié sur les extraits qui la fournissent). Jour et heure sont en temps universel (UTC) : l'heure locale des créateurs n'est pas connue.
B28: • Les compteurs sont arrondis par la plateforme (2 à 3 chiffres significatifs, par exemple 8 300 000) : les petits écarts ne sont pas interprétables. Dans l'extrait Humour, la colonne « video_stats » correspond aux likes (vérifié sur la vidéo commune : 8,3 M de likes dans les deux extraits).
B29: • Variables dérivées : taux d'engagement, classe de durée, nombre de hashtags, hashtags génériques (#fyp, #foryou, #viral, #xyzbca, #parati…), longueur du texte hors hashtags et mentions, mention/duo/stitch/réponse, question ou appel à l'action, week-end, créneau horaire, tranche d'abonnés, vues par abonné.
B30: • Sujet (thème) : déduit de mots-clés présents dans les hashtags, la légende et le pseudo (dog, cat, kids, mom, dance, food, funny, prank…), par ordre de priorité Animaux > Famille & enfants > Lifestyle, musique & sport > Humour & sketchs. Chaque créateur reçoit le sujet le plus fréquent de ses vidéos ; sans mot-clé : « Sujet non déclaré ». Classement automatique et approximatif, relu à la main.
B32: 4. Méthodes statistiques
B33: • Médianes plutôt que moyennes : vues et likes sont très asymétriques (quelques vidéos dépassent 100 M de vues).
B34: • Facteur oui/non : écart de taux d'engagement médian (en points) et test de Mann-Whitney. Facteur continu : corrélation de rang ρ de Spearman (de −1 à +1 ; |ρ| < 0,3 = lien faible), recalculée dans Excel par CORREL sur les colonnes « Rang … » de l'onglet Données. Facteur à plusieurs modalités : écart entre la meilleure et la moins bonne modalité, test de Kruskal-Wallis.
B35: • Seuil : p < 0,05. Verdict : « Effet confirmé » si significatif dans au moins deux échantillons, dans le même sens ; « Effet isolé » si dans un seul ; « Contradictoire » si les sens s'opposent ; sinon « Aucun effet mesurable ».
... B51: • Contact des créateurs : par leurs canaux professionnels publics, en les informant dès le premier contact de l'origine des données et de leur droit de s'y opposer (art. 14 et 21). Toute demande d'effacement est transmise à l'agence. Les chiffres datent de 2021 : à revérifier avant tout contact (exactitude, art. 5).

Sheet Données
A1: Échantillon | B1: Créateur | C1: Thème | D1: Âge (jours) | E1: Jour | F1: Week-end | G1: Heure UTC | H1: Créneau UTC | I1: Durée (s) | J1: Classe de durée | K1: Plus de 15 s | L1: Nb hashtags | M1: Hashtags génériques | N1: Longueur du texte | O1: Légende vide | P1: Mention duo stitch | Q1: Question ou appel | R1: Son original | S1: Stitch autorisé | T1: Abonnés | U1: Tranche abonnés | V1: Vidéos publiées | W1: Vues | X1: Likes | Y1: Commentaires | Z1: Partages | AA1: Engagement | AB1: Top performer | AC1: Vues par abonné | AD1: Compté dans les cumuls | AE1: Rang engagement | AF1: Rang vues | AG1: Rang durée | AH1: Rang hashtags | AI1: Rang longueur | AJ1: Rang abonnés | AK1: Rang vidéos publiées
A2: Tendances | B2: @cacha.7.griselda | C2: Sujet non déclaré | D2: 42 | E2: mardi | F2: =IF(OR(Donnees[[#This Row],[Jour]]="samedi",Donnees[[#This Row],[Jour]]="dimanche"),"Oui","Non") -> Non | G2: 18 | H2: =IF(Donnees[[#This Row],[Heure UTC]]<6,"0-5 h",IF(Donnees[[#This Row],[Heure UTC]]<12,"6-11 h",IF(Donnees[[#This Row],[Heure UTC]]<18,"12-17 h","18-23 h"))) -> 18-23 h | I2: 12 | J2: =IF(Donnees[[#This Row],[Durée (s)]]<=10,"1. ≤ 10 s",IF(Donnees[[#This Row],[Durée (s)]]<=15,"2. 11-15 s",IF(Donnees[[#This Row],[Durée (s)]]<=30,"3. 16-30 s",IF(Donnees[[#This Row],[Durée (s)]]<=60,"4. 31-60 s","5. > 60 s")))) -> 2. 11-15 s | K2: =IF(Donnees[[#This Row],[Durée (s)]]>15,"Oui","Non") -> Non | L2: 3 | M2: Oui | N2: 0 | O2: Non | P2: Non | Q2: Non | U2: =IF(Donnees[[#This Row],[Abonnés]]="","",IF(Donnees[[#This Row],[Abonnés]]<1000000,"1. < 1 M",IF(Donnees[[#This Row],[Abonnés]]<3000000,"2. 1-3 M",IF(Donnees[[#This Row],[Abonnés]]<8000000,"3. 3-8 M","4. ≥ 8 M")))) | W2: 222300000 | X2: 28000000 | Y2: 1500000 | Z2: 2100000 | AA2: =(Donnees[[#This Row],[Likes]]+Donnees[[#This Row],[Commentaires]]+Donnees[[#This Row],[Partages]])/Donnees[[#This Row],[Vues]] -> 0.14215025 | AB2: =IF(Donnees[[#This Row],[Engagement]]>=VLOOKUP(Donnees[[#This Row],[Échantillon]],'Méthode & limites'!$B$9:$D$11,2,FALSE),1,0) -> 0 | AC2: =IF(Donnees[[#This Row],[Abonnés]]="","",Donnees[[#This Row],[Vues]]/Donnees[[#This Row],[Abonnés]]) | AD2: Oui | AE2: =SUMPRODUCT((Donnees[Échantillon]=Donnees[[#This Row],[Échantillon]])*(Donnees[Engagement]<Donnees[[#This Row],[Engagement]]))+(SUMPRODUCT((Donnees[Échantillon]=Donnees[[#This Row],[Échantillon]])*(Donnees[Engagement]=Donnees[[#This Row],[Engagement]]))+1)/2 -> 71 | AF2: =SUMPRODUCT((Donnees[Échantillon]=Donnees[[#This Row],[Échantillon]])*(Donnees[Vues]<Donnees[[#This Row],[Vues]]))+(SUMPRODUCT((Donnees[Échantillon]=Donnees[[#This Row],[Échantillon]])*(Donnees[Vues]=Donnees[[#This Row],[Vues]]))+1)/2 -> 100 | AG2: =SUMPRODUCT((Donnees[Échantillon]=Donnees[[#This Row],[Échantillon]])*(Donnees[Durée (s)]<Donnees[[#This Row],[Durée (s)]]))+(SUMPRODUCT((Donnees[Échantillon]=Donnees[[#This Row],[Échantillon]])*(Donnees[Durée (s)]=Donnees[[#This Row],[Durée (s)]]))+1)/2 -> 56 | AH2: =SUMPRODUCT((Donnees[Échantillon]=Donnees[[#This Row],[Échantillon]])*(Donnees[Nb hashtags]<Donnees[[#This Row],[Nb hashtags]]))+(SUMPRODUCT((Donnees[Échantillon]=Donnees[[#This Row],[Échantillon]])*(Donnees[Nb hashtags]=Donnees[[#This Row],[Nb hashtags]]))+1)/2 -> 52 | AI2: =SUMPRODUCT((Donnees[Échantillon]=Donnees[[#This Row],[Échantillon]])*(Donnees[Longueur du texte]<Donnees[[#This Row],[Longueur du texte]]))+(SUMPRODUCT((Donnees[Échantillon]=Donnees[[#This Row],[Échantillon]])*(Donnees[Longueur du texte]=Donnees[[#This Row],[Longueur du texte]]))+1)/2 -> 16 | AJ2: =IF(Donnees[[#This Row],[Abonnés]]="","",SUMPRODUCT((Donnees[Échantillon]=Donnees[[#This Row],[Échantillon]])*(Donnees[Abonnés]<Donnees[[#This Row],[Abonnés]]))+(SUMPRODUCT((Donnees[Échantillon]=Donnees[[#This Row],[Échantillon]])*(Donnees[Abonnés]=Donnees[[#This Row],[Abonnés]]))+1)/2) | AK2: =IF(Donnees[[#This Row],[Vidéos publiées]]="","",SUMPRODUCT((Donnees[Échantillon]=Donnees[[#This Row],[Échantillon]])*(Donnees[Vidéos publiées]<Donnees[[#This Row],[Vidéos publiées]]))+(SUMPRODUCT((Donnees[Échantillon]=Donnees[[#This Row],[Échantillon]])*(Donnees[Vidéos publiées]=Donnees[[#This Row],[Vidéos publiées]]))+1)/2)
